Workbook

Sheet Dashboard
A1: Market Overview Dashboard
A2: As of 20 December 2025
A3: Major U.S. Indexes | P3: IBD Stock Market Exposure | T3: Market Indicators | X3: Composite Model | AB3: Score
A4: Ticker | B4: Name | C4: Price | D4: Relative Strength 1mo | E4: RS STS 1M % | F4: RS 3M | G4: RS 6M | H4: RS 1Y | I4: % 1D | J4: % 1W | K4: % 1M | L4: % 3M | M4: % 6M | N4: % 1Y | P4: 80-100% | T4: VIX | V4: 14.91 | X4: Monetary Policy (Fed Funds) | AB4: 1.5
A5: SPY | B5: S&P 500 | C5: =Data!Y1 -> 680.59 | F5: 56 | G5: 65 | H5: 73 | I5: =(Price!IW1 - Price!IV1) / Price!IV1 -> 0.0060904401 | J5: =(Price!IW1 - Price!IR1) / Price!IR1 -> -0.0017161464 | K5: =(Price!IW1 - Price!IB1) / Price!IB1 -> 0.027104115 | L5: =(Price!IW1 - Price!GL1) / Price!GL1 -> 0.020619639 | M5: =(Price!IW1 - Price!DZ1) / Price!DZ1 -> 0.14523457 | N5: =(Price!IW1 - Price!D1) / Price!D1 -> 0.12162363 | P5: 60-80% | R5: X | T5: PCC | V5: 0.853 | X5: Liquidty Flow (M2 + Credit) | AB5: 2
A6: QQQ | B6: Nasdaq-100 | C6: =Data!Y2 -> 617.05 | E6: =PERCENTRANK(Data!AA2:'Data'!AV2,Data!AV2) -> 0.571 | F6: 42 | G6: 66 | H6: 76 | I6: =(Price!IW2 - Price!IV2) / Price!IV2 -> 0.013035412 | J6: =(Price!IW2 - Price!IR2) / Price!IR2 -> 0.0055897787 | K6: =(Price!IW2 - Price!IB2) / Price!IB2 -> 0.028639539 | L6: =(Price!IW2 - Price!GL2) / Price!GL2 -> 0.024659582 | M6: =(Price!IW2 - Price!DZ2) / Price!DZ2 -> 0.17125069 | N6: =(Price!IW2 - Price!D2) / Price!D2 -> 0.14657079 | P6: 40-60% | T6: Credit IEI vs.HYG | V6: Good | X6: Rates & Credit (10yr + HYG/IEI) | AB6: 2
A7: DIA | B7: Dow | C7: =Data!Y3 -> 481.15 | E7: =PERCENTRANK(Data!AA3:'Data'!AV3,Data!AV3) -> 0.714 | F7: 71 | G7: 71 | H7: 70 | I7: =(Price!IW3 - Price!IV3) / Price!IV3 -> 0.0013319182 | J7: =(Price!IW3 - Price!IR3) / Price!IR3 -> -0.0087556654 | K7: =(Price!IW3 - Price!IB3) / Price!IB3 -> 0.041991511 | L7: =(Price!IW3 - Price!GL3) / Price!GL3 -> 0.037699226 | M7: =(Price!IW3 - Price!DZ3) / Price!DZ3 -> 0.14081468 | N7: =(Price!IW3 - Price!D3) / Price!D3 -> 0.097588795 | P7: 20-40% | T7: U.S. Dollar | V7: 98.72 | X7: Tape Strength (Breadth+ U/D + Net High/Lows) | AB7: 1.5
A8: IWM | B8: Russell 2000 | C8: =Data!Y4 -> 250.79 | E8: =PERCENTRANK(Data!AA4:'Data'!AV4,Data!AV4) -> 0.809 | F8: 64 | G8: 74 | H8: 73 | I8: =(Price!IW4 - Price!IV4) / Price!IV4 -> 0.0083631539 | J8: =(Price!IW4 - Price!IR4) / Price!IR4 -> -0.012054363 | K8: =(Price!IW4 - Price!IB4) / Price!IB4 -> 0.07436919 | L8: =(Price!IW4 - Price!GL4) / Price!GL4 -> 0.026187651 | M8: =(Price!IW4 - Price!DZ4) / Price!DZ4 -> 0.19874767 | N8: =(Price!IW4 - Price!D4) / Price!D4 -> 0.069740659 | P8: 0-20% | T8: Distribution Days | V8: 5 | X8: Sentiment (VIX + Put/Call ) | AB8: 1.5
A9: RSP | B9: S&P 500 EW | C9: =Data!Y5 -> 192.88 | E9: =PERCENTRANK(Data!AA5:'Data'!AV5,Data!AV5) -> 0.809 | F9: 67 | G9: 59 | H9: 59 | I9: =(Price!IW5 - Price!IV5) / Price!IV5 -> 0.0036424186 | J9: =(Price!IW5 - Price!IR5) / Price!IR5 -> -0.0027402926 | K9: =(Price!IW5 - Price!IB5) / Price!IB5 -> 0.045816841 | L9: =(Price!IW5 - Price!GL5) / Price!GL5 -> 0.023344652 | M9: =(Price!IW5 - Price!DZ5) / Price!DZ5 -> 0.085730369 | N9: =(Price!IW5 - Price!D5) / Price!D5 -> 0.062348535 | T9: Up/Down Daily Ratio | V9: 2.6 | X9: Total Score | AB9: 8.5
A10: QQQE | B10: Nasdaq-100 EW | C10: =Data!Y6 -> 103.27 | E10: =PERCENTRANK(Data!AA6:'Data'!AV6,Data!AV6) -> 0.857 | F10: 56 | G10: 56 | H10: 65 | I10: =(Price!IW6 - Price!IV6) / Price!IV6 -> 0.0076104986 | J10: =(Price!IW6 - Price!IR6) / Price!IR6 -> 0.00029058504 | K10: =(Price!IW6 - Price!IB6) / Price!IB6 -> 0.042604745 | L10: =(Price!IW6 - Price!GL6) / Price!GL6 -> 0.019447187 | M10: =(Price!IW6 - Price!DZ6) / Price!DZ6 -> 0.088427487 | N10: =(Price!IW6 - Price!D6) / Price!D6 -> 0.088656968 | P10: Market Type | T10: Up/Down Weekly Ratio | V10: 1.1
A11: EDOW | B11: Dow EW | C11: =Data!Y7 -> 41.2032 | E11: =PERCENTRANK(Data!AA7:'Data'!AV7,Data!AV7) -> 0.571 | F11: 69 | G11: 67 | H11: 68 | I11: =(Price!IW7 - Price!IV7) / Price!IV7 -> -0.00013831963 | J11: =(Price!IW7 - Price!IR7) / Price!IR7 -> -0.010014416 | K11: =(Price!IW7 - Price!IB7) / Price!IB7 -> 0.029115204 | L11: =(Price!IW7 - Price!GL7) / Price!GL7 -> 0.031878047 | M11: =(Price!IW7 - Price!DZ7) / Price!DZ7 -> 0.11724463 | N11: =(Price!IW7 - Price!D7) / Price!D7 -> 0.10971898 | P11: Bull Quiet | T11: Up/Down Monthly Ratio | V11: 1.2 | X11: Hot Sectors / Industry Groups
A12: MDY | B12: S&P 500 Midcap | C12: =Data!Y8 -> 611.57 | E12: =PERCENTRANK(Data!AA8:'Data'!AV8,Data!AV8) -> 0.761 | F12: 68 | G12: 62 | H12: 59 | I12: =(Price!IW8 - Price!IV8) / Price!IV8 -> 0.0057559163 | J12: =(Price!IW8 - Price!IR8) / Price!IR8 -> -0.0025117842 | K12: =(Price!IW8 - Price!IB8) / Price!IB8 -> 0.058280988 | L12: =(Price!IW8 - Price!GL8) / Price!GL8 -> 0.021104303 | M12: =(Price!IW8 - Price!DZ8) / Price!DZ8 -> 0.10769593 | N12: =(Price!IW8 - Price!D8) / Price!D8 -> 0.020524972 | P12: Bull Volatile | R12: X | T12: A/D Daily Ratio (QSHR) | V12: 1.4 | X12: QQQE, IWM, XLF, XLC, XLI, XTL, XRT, PEJ, XBI, XPH, KBE, KIE, GDX, SIL, XME, GLD, SLV, PALL, DBB, CPER, EWC, EWP, EWL, EWI,
A13: IWN | B13: Russell Value | C13: =Data!Y9 -> 184.45 | E13: =PERCENTRANK(Data!AA9:'Data'!AV9,Data!AV9) -> 0.666 | F13: 75 | G13: 77 | H13: 75 | I13: =(Price!IW9 - Price!IV9) / Price!IV9 -> 0.00016267216 | J13: =(Price!IW9 - Price!IR9) / Price!IR9 -> -0.015899269 | K13: =(Price!IW9 - Price!IB9) / Price!IB9 -> 0.07739486 | L13: =(Price!IW9 - Price!GL9) / Price!GL9 -> 0.039389158 | M13: =(Price!IW9 - Price!DZ9) / Price!DZ9 -> 0.20406032 | N13: =(Price!IW9 - Price!D9) / Price!D9 -> 0.056656737 | P13: Bear Quiet | T13: A/D Weekly Ratio | V13: 1
A14: IWO | B14: Russell Growth | C14: =Data!Y10 -> 329.61 | E14: =PERCENTRANK(Data!AA10:'Data'!AV10,Data!AV10) -> 0.714 | F14: 41 | G14: 70 | H14: 73 | I14: =(Price!IW10 - Price!IV10) / Price!IV10 -> 0.016436413 | J14: =(Price!IW10 - Price!IR10) / Price!IR10 -> -0.0099423285 | K14: =(Price!IW10 - Price!IB10) / Price!IB10 -> 0.070266584 | L14: =(Price!IW10 - Price!GL10) / Price!GL10 -> 0.014340668 | M14: =(Price!IW10 - Price!DZ10) / Price!DZ10 -> 0.19359044 | N14: =(Price!IW10 - Price!D10) / Price!D10 -> 0.076242408 | P14: Bear Volatile | T14: A/D Monthly Ratio | V14: 1.4
P15: Sideways Quiet
A16: U.S. Sectors | P16: Sideways Volatile | T16: Macro
A17: Ticker | B17: Name | C17: Price | D17: Relative Strength 1mo | E17: RS STS % | F17: RS 3M | G17: RS 6M | H17: RS 1Y | I17: % 1D | J17: % 1W | K17: % 1M | L17: % 3M | M17: % 6M | N17: % 1Y | T17: Fed Funds | V17: 3.88
A18: XLC | B18: Communication | C18: =Data!Y11 -> 116.52 | E18: =PERCENTRANK(Data!AA11:'Data'!AV11,Data!AV11) -> 0.809 | F18: 65 | G18: 67 | H18: 70 | I18: =(Price!IW11 - Price!IV11) / Price!IV11 -> 0.0004292951 | J18: =(Price!IW11 - Price!IR11) / Price!IR11 -> -0.00025740026 | K18: =(Price!IW11 - Price!IB11) / Price!IB11 -> 0.047935965 | L18: =(Price!IW11 - Price!GL11) / Price!GL11 -> -0.017372238 | M18: =(Price!IW11 - Price!DZ11) / Price!DZ11 -> 0.13302217 | N18: =(Price!IW11 - Price!D11) / Price!D11 -> 0.14990625 | P18: Trend Condition (QQQ) | T18: M2 Money | V18: 22.3 | X18: Market Correlations (last 30 days) S&P500
A19: XLY | B19: Consumer Disc. | C19: =Data!Y12 -> 121.85 | E19: =PERCENTRANK(Data!AA12:'Data'!AV12,Data!AV12) -> 0.476 | F19: 78 | G19: 76 | H19: 70 | I19: =(Price!IW12 - Price!IV12) / Price!IV12 -> -0.0040052313 | J19: =(Price!IW12 - Price!IR12) / Price!IR12 -> 0.0095277548 | K19: =(Price!IW12 - Price!IB12) / Price!IB12 -> -0.45726248 | L19: =(Price!IW12 - Price!GL12) / Price!GL12 -> -0.49267216 | M19: =(Price!IW12 - Price!DZ12) / Price!DZ12 -> -0.42163471 | N19: =(Price!IW12 - Price!D12) / Price!D12 -> -0.48948383 | P19: Above 5DMA | R19: Yes | T19: 10 yr | V19: 4.15 | X19: Correlated: | Z19: Dow, Nasdaq-100, Russell, Nikkei
A20: XLP | B20: Consumer Staples | C20: =Data!Y13 -> 78.78 | E20: =PERCENTRANK(Data!AA13:'Data'!AV13,Data!AV13) -> 0.523 | F20: 67 | G20: 35 | H20: 34 | I20: =(Price!IW13 - Price!IV13) / Price!IV13 -> -0.0051774214 | J20: =(Price!IW13 - Price!IR13) / Price!IR13 -> -0.0080584236 | K20: =(Price!IW13 - Price!IB13) / Price!IB13 -> 0.029669324 | L20: =(Price!IW13 - Price!GL13) / Price!GL13 -> 0.010518214 | M20: =(Price!IW13 - Price!DZ13) / Price!DZ13 -> -0.027647494 | N20: =(Price!IW13 - Price!D13) / Price!D13 -> -0.034677123 | P20: Above 10DMA | R20: Yes
A21: XLE | B21: Energy | C21: =Data!Y14 -> 44.13 | E21: =PERCENTRANK(Data!AA14:'Data'!AV14,Data!AV14) -> 0.047 | F21: 37 | G21: 33 | H21: 39 | I21: =(Price!IW14 - Price!IV14) / Price!IV14 -> 0 | J21: =(Price!IW14 - Price!IR14) / Price!IR14 -> -0.030323006 | K21: =(Price!IW14 - Price!IB14) / Price!IB14 -> -0.50901202 | L21: =(Price!IW14 - Price!GL14) / Price!GL14 -> -0.49663511 | M21: =(Price!IW14 - Price!DZ14) / Price!DZ14 -> -0.50404585 | N21: =(Price!IW14 - Price!D14) / Price!D14 -> -0.49427 | P21: Above 20DMA | R21: Yes | T21: Breadth & Participation
A22: XLF | B22: Financial | C22: =Data!Y15 -> 54.84 | E22: =PERCENTRANK(Data!AA15:'Data'!AV15,Data!AV15) -> 0.809 | F22: 75 | G22: 61 | H22: 62 | I22: =(Price!IW15 - Price!IV15) / Price!IV15 -> 0.0055005501 | J22: =(Price!IW15 - Price!IR15) / Price!IR15 -> -0.0020018198 | K22: =(Price!IW15 - Price!IB15) / Price!IB15 -> 0.063615206 | L22: =(Price!IW15 - Price!GL15) / Price!GL15 -> 0.015555556 | M22: =(Price!IW15 - Price!DZ15) / Price!DZ15 -> 0.088959492 | N22: =(Price!IW15 - Price!D15) / Price!D15 -> 0.10899899 | P22: Above 50DMA | R22: Yes | T22: % Price Above 10DMA | V22: 0.5 | X22: Uncorrelated: | Z22: Dollar, Bonds, Heating Oil, Soybeans, Nat Gas, Wheat, Gasoline
A23: XLV | B23: Health Care | C23: =Data!Y16 -> 154.94 | E23: =PERCENTRANK(Data!AA16:'Data'!AV16,Data!AV16) -> 0.523 | F23: 80 | G23: 81 | H23: 73 | I23: =(Price!IW16 - Price!IV16) / Price!IV16 -> 0.0066922227 | J23: =(Price!IW16 - Price!IR16) / Price!IR16 -> 0.0057120602 | K23: =(Price!IW16 - Price!IB16) / Price!IB16 -> 0.017133854 | L23: =(Price!IW16 - Price!GL16) / Price!GL16 -> 0.13401156 | M23: =(Price!IW16 - Price!DZ16) / Price!DZ16 -> 0.16847662 | N23: =(Price!IW16 - Price!D16) / Price!D16 -> 0.11219582 | P23: Above 200DMA | R23: Yes | T23: % Price Above 20DMA | V23: 0.55
A24: XLI | B24: Industrial | C24: =Data!Y17 -> 155.86 | E24: =PERCENTRANK(Data!AA17:'Data'!AV17,Data!AV17) -> 0.857 | F24: 59 | G24: 52 | H24: 68 | I24: =(Price!IW17 - Price!IV17) / Price!IV17 -> 0.008606743 | J24: =(Price!IW17 - Price!IR17) / Price!IR17 -> -0.0056143933 | K24: =(Price!IW17 - Price!IB17) / Price!IB17 -> 0.036647822 | L24: =(Price!IW17 - Price!GL17) / Price!GL17 -> 0.01869281 | M24: =(Price!IW17 - Price!DZ17) / Price!DZ17 -> 0.094753108 | N24: =(Price!IW17 - Price!D17) / Price!D17 -> 0.13311523 | T24: % Price Above 50DMA | V24: 0.53
A25: XLB | B25: Materials | C25: =Data!Y18 -> 45.37 | E25: =PERCENTRANK(Data!AA18:'Data'!AV18,Data!AV18) -> 0.523 | F25: 71 | G25: 52 | H25: 51 | I25: =(Price!IW18 - Price!IV18) / Price!IV18 -> 0.0044277175 | J25: =(Price!IW18 - Price!IR18) / Price!IR18 -> 0.0048726467 | K25: =(Price!IW18 - Price!IB18) / Price!IB18 -> -0.47084208 | L25: =(Price!IW18 - Price!GL18) / Price!GL18 -> -0.49795286 | M25: =(Price!IW18 - Price!DZ18) / Price!DZ18 -> -0.47500579 | N25: =(Price!IW18 - Price!D18) / Price!D18 -> -0.48699683 | P25: Nasdaq Net 52wk New High/Low | T25: % Price Above 200DMA | V25: 0.64
A26: XLRE | B26: Real Estate | C26: =Data!Y19 -> 40.33 | E26: =PERCENTRANK(Data!AA19:'Data'!AV19,Data!AV19) -> 0.095 | F26: 32 | G26: 28 | H26: 30 | I26: =(Price!IW19 - Price!IV19) / Price!IV19 -> -0.0037055336 | J26: =(Price!IW19 - Price!IR19) / Price!IR19 -> -0.010306748 | K26: =(Price!IW19 - Price!IB19) / Price!IB19 -> -0.0044433473 | L26: =(Price!IW19 - Price!GL19) / Price!GL19 -> -0.032157427 | M26: =(Price!IW19 - Price!DZ19) / Price!DZ19 -> -0.035859431 | N26: =(Price!IW19 - Price!D19) / Price!D19 -> -0.053508566 | P26: Daily | R26: 44 | T26: % Above 20, 50, 200 | V26: 0.42
A27: XLK | B27: Technology | C27: =Data!Y20 -> 144.6 | E27: =PERCENTRANK(Data!AA20:'Data'!AV20,Data!AV20) -> 0.333 | F27: 34 | G27: 64 | H27: 79 | I27: =(Price!IW20 - Price!IV20) / Price!IV20 -> 0.02161933 | J27: =(Price!IW20 - Price!IR20) / Price!IR20 -> 0.0063330782 | K27: =(Price!IW20 - Price!IB20) / Price!IB20 -> -0.48535431 | L27: =(Price!IW20 - Price!GL20) / Price!GL20 -> -0.48843133 | M27: =(Price!IW20 - Price!DZ20) / Price!DZ20 -> -0.39885258 | N27: =(Price!IW20 - Price!D20) / Price!D20 -> -0.40109344 | P27: Weekly | R27: 165
A28: XLU | B28: Utilities | C28: =Data!Y21 -> 42.63 | E28: =PERCENTRANK(Data!AA21:'Data'!AV21,Data!AV21) -> 0.19 | F28: 31 | G28: 45 | H28: 62 | I28: =(Price!IW21 - Price!IV21) / Price!IV21 -> -0.012737378 | J28: =(Price!IW21 - Price!IR21) / Price!IR21 -> -0.0046696241 | K28: =(Price!IW21 - Price!IB21) / Price!IB21 -> -0.51814174 | L28: =(Price!IW21 - Price!GL21) / Price!GL21 -> -0.49964789 | M28: =(Price!IW21 - Price!DZ21) / Price!DZ21 -> -0.47227036 | N28: =(Price!IW21 - Price!D21) / Price!D21 -> -0.4465074 | P28: Monthly | R28: 1393
A30: U.S. Sub-Sectors / Industry Groups | P30: U.S. Sub-Sectors / Industry Groups
A31: Ticker | B31: Name | C31: Price | D31: Relative Strength 1mo | E31: RS STS % | F31: RS 3M | G31: RS 6M | H31: RS 1Y | I31: % 1D | J31: % 1W | K31: % 1M | L31: % 3M | M31: % 6M | N31: % 1Y | P31: Ticker | Q31: Name | R31: Price | S31: Relative Strength 1mo | T31: RS STS % | U31: RS 3M | V31: RS 6M | W31: RS 1Y | X31: % 1D | Y31: % 1W | Z31: % 1M | AA31: % 3M | AB31: % 6M | AC31: % 1Y
A32: SOXX | B32: =Data!C22 -> iShares:Semiconductor | C32: =Data!Y22 -> 299.81 | E32: =PERCENTRANK(Data!AA22:'Data'!AV22,Data!AV22) -> 0.619 | F32: 46 | G32: 81 | H32: 87 | I32: =(Price!IW22 - Price!IV22) / Price!IV22 -> 0.026605944 | J32: =(Price!IW22 - Price!IR22) / Price!IR22 -> 0.00110191 | K32: =(Price!IW22 - Price!IB22) / Price!IB22 -> 0.064628387 | L32: =(Price!IW22 - Price!GL22) / Price!GL22 -> 0.11110699 | M32: =(Price!IW22 - Price!DZ22) / Price!DZ22 -> 0.33183777 | N32: =(Price!IW22 - Price!D22) / Price!D22 -> 0.31819381 | P32: GLD | Q32: =Data!C96 -> SPDR Gold | R32: =Data!Y96 -> 399.02 | T32: =PERCENTRANK(Data!AA96:'Data'!AV96,Data!AV96) -> 0.904 | U32: 84 | V32: 89 | W32: 90 | X32: =(Price!IW96 - Price!IV96) / Price!IV96 -> 0.0011290363 | Y32: =(Price!IW96 - Price!IR96) / Price!IR96 -> 0.0090532066 | Z32: =(Price!IW96 - Price!IB96) / Price!IB96 -> 0.064166844 | AA32: =(Price!IW96 - Price!GL96) / Price!GL96 -> 0.15641211 | AB32: =(Price!IW96 - Price!DZ96) / Price!DZ96 -> 0.28662174 | AC32: =(Price!IW96 - Price!D96) / Price!D96 -> 0.62945116
A33: SMH | B33: =Data!C23 -> VanEck:Semiconductor | C33: =Data!Y23 -> 356.23 | E33: =PERCENTRANK(Data!AA23:'Data'!AV23,Data!AV23) -> 0.619 | F33: 47 | G33: 82 | H33: 89 | I33: =(Price!IW23 - Price!IV23) / Price!IV23 -> 0.025860331 | J33: =(Price!IW23 - Price!IR23) / Price!IR23 -> 0.0059584322 | K33: =(Price!IW23 - Price!IB23) / Price!IB23 -> 0.049463823 | L33: =(Price!IW23 - Price!GL23) / Price!GL23 -> 0.10572058 | M33: =(Price!IW23 - Price!DZ23) / Price!DZ23 -> 0.36869405 | N33: =(Price!IW23 - Price!D23) / Price!D23 -> 0.40663376 | P33: SLV | Q33: =Data!C97 -> IShares:Silver Trust | R33: =Data!Y97 -> 60.93 | T33: =PERCENTRANK(Data!AA97:'Data'!AV97,Data!AV97) -> 0.952 | U33: 97 | V33: 97 | W33: 96 | X33: =(Price!IW97 - Price!IV97) / Price!IV97 -> 0.027140931 | Y33: =(Price!IW97 - Price!IR97) / Price!IR97 -> 0.086096257 | Z33: =(Price!IW97 - Price!IB97) / Price!IB97 -> 0.31173305 | AA33: =(Price!IW97 - Price!GL97) / Price!GL97 -> 0.52172827 | AB33: =(Price!IW97 - Price!DZ97) / Price!DZ97 -> 0.86216381 | AC33: =(Price!IW97 - Price!D97) / Price!D97 -> 1.1917266
A34: XSD | B34: =Data!C24 -> SS SPDR S&P Semiconductr | C34: =Data!Y24 -> 327.17 | E34: =PERCENTRANK(Data!AA24:'Data'!AV24,Data!AV24) -> 0.619 | F34: 25 | G34: 76 | H34: 84 | I34: =(Price!IW24 - Price!IV24) / Price!IV24 -> 0.025386279 | J34: =(Price!IW24 - Price!IR24) / Price!IR24 -> -0.0029256697 | K34: =(Price!IW24 - Price!IB24) / Price!IB24 -> 0.092132056 | L34: =(Price!IW24 - Price!GL24) / Price!GL24 -> 0.011219633 | M34: =(Price!IW24 - Price!DZ24) / Price!DZ24 -> 0.33970763 | N34: =(Price!IW24 - Price!D24) / Price!D24 -> 0.2338588 | P34: UNG | Q34: =Data!C98 -> United States Nat Gas | R34: =Data!Y98 -> 12.19 | T34: =PERCENTRANK(Data!AA98:'Data'!AV98,Data!AV98) -> 0.095 | U34: 15 | V34: 13 | W34: 14 | X34: =(Price!IW98 - Price!IV98) / Price!IV98 -> 0.013300083 | Y34: =(Price!IW98 - Price!IR98) / Price!IR98 -> -0.042419482 | Z34: =(Price!IW98 - Price!IB98) / Price!IB98 -> -0.1707483 | AA34: =(Price!IW98 - Price!GL98) / Price!GL98 -> 0.0032921811 | AB34: =(Price!IW98 - Price!DZ98) / Price!DZ98 -> -0.30973952 | AC34: =(Price!IW98 - Price!D98) / Price!D98 -> -0.12616487
A35: IGV | B35: =Data!C25 -> iShares:Expand Tch-Sftwr | C35: =Data!Y25 -> 107.76 | E35: =PERCENTRANK(Data!AA25:'Data'!AV25,Data!AV25) -> 0.714 | F35: 24 | G35: 25 | H35: 45 | I35: =(Price!IW25 - Price!IV25) / Price!IV25 -> 0.014880392 | J35: =(Price!IW25 - Price!IR25) / Price!IR25 -> -0.0019449847 | K35: =(Price!IW25 - Price!IB25) / Price!IB25 -> 0.037250938 | L35: =(Price!IW25 - Price!GL25) / Price!GL25 -> -0.085151541 | M35: =(Price!IW25 - Price!DZ25) / Price!DZ25 -> 0.025211683 | N35: =(Price!IW25 - Price!D25) / Price!D25 -> 0.0079506127 | P35: USO | Q35: =Data!C99 -> United States Oil Fund | R35: =Data!Y99 -> 68.03 | T35: =PERCENTRANK(Data!AA99:'Data'!AV99,Data!AV99) -> 0.142 | U35: 22 | V35: 16 | W35: 21 | X35: =(Price!IW99 - Price!IV99) / Price!IV99 -> 0.01250186 | Y35: =(Price!IW99 - Price!IR99) / Price!IR99 -> -0.011335562 | Z35: =(Price!IW99 - Price!IB99) / Price!IB99 -> -0.040208804 | AA35: =(Price!IW99 - Price!GL99) / Price!GL99 -> -0.073791695 | AB35: =(Price!IW99 - Price!DZ99) / Price!DZ99 -> -0.18154475 | AC35: =(Price!IW99 - Price!D99) / Price!D99 -> -0.076933514
A36: XSW | B36: =Data!C26 -> SS SPDR S&P Sftwre & Svc | C36: =Data!Y26 -> 190.7197 | E36: =PERCENTRANK(Data!AA26:'Data'!AV26,Data!AV26) -> 0.761 | F36: 30 | G36: 32 | H36: 45 | I36: =(Price!IW26 - Price!IV26) / Price!IV26 -> 0.0081921023 | J36: =(Price!IW26 - Price!IR26) / Price!IR26 -> -0.0096598816 | K36: =(Price!IW26 - Price!IB26) / Price!IB26 -> 0.064084524 | L36: =(Price!IW26 - Price!GL26) / Price!GL26 -> -0.070747905 | M36: =(Price!IW26 - Price!DZ26) / Price!DZ26 -> 0.062327745 | N36: =(Price!IW26 - Price!D26) / Price!D26 -> -0.06326277 | P36: DBA | Q36: =Data!C100 -> Invesco DB MS Agri | R36: =Data!Y100 -> 26.2 | T36: =PERCENTRANK(Data!AA100:'Data'!AV100,Data!AV100) -> 0.142 | U36: 35 | V36: 30 | W36: 30 | X36: =(Price!IW100 - Price!IV100) / Price!IV100 -> 0.0019120459 | Y36: =(Price!IW100 - Price!IR100) / Price!IR100 -> -0.012066365 | Z36: =(Price!IW100 - Price!IB100) / Price!IB100 -> 0.0042161748 | AA36: =(Price!IW100 - Price!GL100) / Price!GL100 -> -0.024208566 | AB36: =(Price!IW100 - Price!DZ100) / Price!DZ100 -> -0.0079515335 | AC36: =(Price!IW100 - Price!D100) / Price!D100 -> -0.056195965
A37: IGM | B37: =Data!C27 -> iShares:Exp Tech Sector | C37: =Data!Y27 -> 129.5 | E37: =PERCENTRANK(Data!AA27:'Data'!AV27,Data!AV27) -> 0.523 | F37: 33 | G37: 68 | H37: 80 | I37: =(Price!IW27 - Price!IV27) / Price!IV27 -> 0.018722467 | J37: =(Price!IW27 - Price!IR27) / Price!IR27 -> 0.00061814248 | K37: =(Price!IW27 - Price!IB27) / Price!IB27 -> 0.028267429 | L37: =(Price!IW27 - Price!GL27) / Price!GL27 -> 0.014333829 | M37: =(Price!IW27 - Price!DZ27) / Price!DZ27 -> 0.22043163 | N37: =(Price!IW27 - Price!D27) / Price!D27 -> 0.21084619 | P37: CORN | Q37: =Data!C101 -> Teucrium:Corn | R37: =Data!Y101 -> 17.7905 | T37: =PERCENTRANK(Data!AA101:'Data'!AV101,Data!AV101) -> 0.428 | U37: 49 | V37: 48 | W37: 32 | X37: =(Price!IW101 - Price!IV101) / Price!IV101 -> -0.0027746637 | Y37: =(Price!IW101 - Price!IR101) / Price!IR101 -> 0.0022816901 | Z37: =(Price!IW101 - Price!IB101) / Price!IB101 -> 0.0025641026 | AA37: =(Price!IW101 - Price!GL101) / Price!GL101 -> 0.010249858 | AB37: =(Price!IW101 - Price!DZ101) / Price!DZ101 -> -0.029961832 | AC37: =(Price!IW101 - Price!D101) / Price!D101 -> -0.031018519
A38: VGT | B38: =Data!C28 -> Vanguard InfoTch Idx;ETF | C38: =Data!Y28 -> 755.54 | E38: =PERCENTRANK(Data!AA28:'Data'!AV28,Data!AV28) -> 0.571 | F38: 30 | G38: 60 | H38: 78 | I38: =(Price!IW28 - Price!IV28) / Price!IV28 -> 0.020145284 | J38: =(Price!IW28 - Price!IR28) / Price!IR28 -> 0.0021354768 | K38: =(Price!IW28 - Price!IB28) / Price!IB28 -> 0.024363789 | L38: =(Price!IW28 - Price!GL28) / Price!GL28 -> 0.0031733386 | M38: =(Price!IW28 - Price!DZ28) / Price!DZ28 -> 0.20217032 | N38: =(Price!IW28 - Price!D28) / Price!D28 -> 0.16601077 | P38: DBB | Q38: =Data!C102 -> Invesco DB MS BMtl | R38: =Data!Y102 -> 22.64 | T38: =PERCENTRANK(Data!AA102:'Data'!AV102,Data!AV102) -> 1 | U38: 80 | V38: 81 | W38: 78 | X38: =(Price!IW102 - Price!IV102) / Price!IV102 -> 0.011165699 | Y38: =(Price!IW102 - Price!IR102) / Price!IR102 -> 0.020739405 | Z38: =(Price!IW102 - Price!IB102) / Price!IB102 -> 0.056462902 | AA38: =(Price!IW102 - Price!GL102) / Price!GL102 -> 0.12692882 | AB38: =(Price!IW102 - Price!DZ102) / Price!DZ102 -> 0.19851773 | AC38: =(Price!IW102 - Price!D102) / Price!D102 -> 0.12917706
A39: XT | B39: =Data!C29 -> iShares:Fut Exp Tch | C39: =Data!Y29 -> 69.8 | E39: =PERCENTRANK(Data!AA29:'Data'!AV29,Data!AV29) -> 0.142 | F39: 20 | G39: 31 | H39: 62 | I39: =(Price!IW29 - Price!IV29) / Price!IV29 -> 0.01071532 | J39: =(Price!IW29 - Price!IR29) / Price!IR29 -> -0.069085089 | K39: =(Price!IW29 - Price!IB29) / Price!IB29 -> -0.033910035 | L39: =(Price!IW29 - Price!GL29) / Price!GL29 -> -0.030151452 | M39: =(Price!IW29 - Price!DZ29) / Price!DZ29 -> 0.11966635 | N39: =(Price!IW29 - Price!D29) / Price!D29 -> 0.1214653 | P39: PALL | Q39: =Data!C103 -> abrdn:Physical Palladium | R39: =Data!Y103 -> 156.06 | T39: =PERCENTRANK(Data!AA103:'Data'!AV103,Data!AV103) -> 1 | U39: 96 | V39: 94 | W39: 95 | X39: =(Price!IW103 - Price!IV103) / Price!IV103 -> 0.013639906 | Y39: =(Price!IW103 - Price!IR103) / Price!IR103 -> 0.1432967 | Z39: =(Price!IW103 - Price!IB103) / Price!IB103 -> 0.23602091 | AA39: =(Price!IW103 - Price!GL103) / Price!GL103 -> 0.44019934 | AB39: =(Price!IW103 - Price!DZ103) / Price!DZ103 -> 0.62732013 | AC39: =(Price!IW103 - Price!D103) / Price!D103 -> 0.80062305
A40: CIBR | B40: =Data!C30 -> FT II:Nsdq Cybersecurity | C40: =Data!Y30 -> 73.12 | E40: =PERCENTRANK(Data!AA30:'Data'!AV30,Data!AV30) -> 0.285 | F40: 24 | G40: 26 | H40: 51 | I40: =(Price!IW30 - Price!IV30) / Price!IV30 -> 0.01050304 | J40: =(Price!IW30 - Price!IR30) / Price!IR30 -> -0.010420896 | K40: =(Price!IW30 - Price!IB30) / Price!IB30 -> -0.0035431998 | L40: =(Price!IW30 - Price!GL30) / Price!GL30 -> -0.049154746 | M40: =(Price!IW30 - Price!DZ30) / Price!DZ30 -> 0.013163364 | N40: =(Price!IW30 - Price!D30) / Price!D30 -> 0.090692124 | P40: URA | Q40: =Data!C104 -> Glbl X Uranium ETF | R40: =Data!Y104 -> 45.89 | T40: =PERCENTRANK(Data!AA104:'Data'!AV104,Data!AV104) -> 0.571 | U40: 14 | V40: 48 | W40: 88 | X40: =(Price!IW104 - Price!IV104) / Price!IV104 -> 0.043903549 | Y40: =(Price!IW104 - Price!IR104) / Price!IR104 -> -0.0034744843 | Z40: =(Price!IW104 - Price!IB104) / Price!IB104 -> 0.016614976 | AA40: =(Price!IW104 - Price!GL104) / Price!GL104 -> -0.089484127 | AB40: =(Price!IW104 - Price!DZ104) / Price!DZ104 -> 0.24802828 | AC40: =(Price!IW104 - Price!D104) / Price!D104 -> 0.58734002
A41: BOTZ | B41: =Data!C31 -> Glbl X Rob & Art Intel | C41: =Data!Y31 -> 35.96 | E41: =PERCENTRANK(Data!AA31:'Data'!AV31,Data!AV31) -> 0.619 | F41: 31 | G41: 55 | H41: 68 | I41: =(Price!IW31 - Price!IV31) / Price!IV31 -> 0.016968326 | J41: =(Price!IW31 - Price!IR31) / Price!IR31 -> -0.011544805 | K41: =(Price!IW31 - Price!IB31) / Price!IB31 -> 0.062647754 | L41: =(Price!IW31 - Price!GL31) / Price!GL31 -> 0 | M41: =(Price!IW31 - Price!DZ31) / Price!DZ31 -> 0.18095238 | N41: =(Price!IW31 - Price!D31) / Price!D31 -> 0.081503759 | P41: UGA | Q41: =Data!C105 -> United States Gas | R41: =Data!Y105 -> 61.77 | T41: =PERCENTRANK(Data!AA105:'Data'!AV105,Data!AV105) -> 0.095 | U41: 22 | V41: 22 | W41: 28 | X41: =(Price!IW105 - Price!IV105) / Price!IV105 -> 0.0068459658 | Y41: =(Price!IW105 - Price!IR105) / Price!IR105 -> -0.023399209 | Z41: =(Price!IW105 - Price!IB105) / Price!IB105 -> -0.079159213 | AA41: =(Price!IW105 - Price!GL105) / Price!GL105 -> -0.035767304 | AB41: =(Price!IW105 - Price!DZ105) / Price!DZ105 -> -0.081828317 | AC41: =(Price!IW105 - Price!D105) / Price!D105 -> -0.0055638197
...

Sheet Data
A1: #VALUE! | B1: {=_FV(A1,"ticker symbol",TRUE)} -> SPY | C1: {=_FV(A1,"Name")} -> SPDR S&P 500 | D1: {=TRANSPOSE(_xlfn.STOCKHISTORY(B1, WORKDAY(TODAY(), -23), TODAY(), 0, 0, 1))} -> 662.63 | E1: 652.53 | F1: 659.03 | G1: 668.73 | H1: 675.02 | I1: 679.68 | J1: 683.39 | K1: 680.27 | L1: 681.53 | M1: 683.89 | N1: 684.39 | O1: 685.69 | P1: 683.63 | Q1: 683.04 | R1: 687.57 | S1: 689.17 | T1: 681.76 | U1: 680.73 | V1: 678.87 | W1: 671.4 | X1: 676.47 | Y1: 680.59 | AA1: 1 | AB1: 2 | AC1: 3 | AD1: 4 | AE1: 5 | AF1: 6 | AG1: 7 | AH1: 8 | AI1: 9 | AJ1: 10 | AK1: 11 | AL1: 12 | AM1: 13 | AN1: 14 | AO1: 15 | AP1: 16 | AQ1: 17 | AR1: 18 | AS1: 19 | AT1: 20 | AU1: 21 | AV1: 22
A2: #VALUE! | B2: {=_FV(A2,"ticker symbol",TRUE)} -> QQQ | C2: {=_FV(A2,"Name")} -> Invesco QQQ Trust 1 | D2: {=TRANSPOSE(_xlfn.STOCKHISTORY(B2, WORKDAY(TODAY(), -23), TODAY(), 0, 0, 1))} -> 599.87 | E2: 585.67 | F2: 590.07 | G2: 605.16 | H2: 608.89 | I2: 614.27 | J2: 619.25 | K2: 617.17 | L2: 622 | M2: 623.52 | N2: 622.94 | O2: 625.48 | P2: 624.28 | Q2: 625.05 | R2: 627.61 | S2: 625.58 | T2: 613.62 | U2: 610.54 | V2: 611.75 | W2: 600.41 | X2: 609.11 | Y2: 617.05 | AA2: =D2/D$1 -> 0.90528651 | AB2: =E2/E$1 -> 0.89753728 | AC2: =F2/F$1 -> 0.89536136 | AD2: =G2/G$1 -> 0.90493921 | AE2: =H2/H$1 -> 0.90203253 | AF2: =I2/I$1 -> 0.90376354 | AG2: =J2/J$1 -> 0.90614437 | AH2: =K2/K$1 -> 0.90724271 | ... AV2: =Y2/Y$1 -> 0.90663983
A3: #VALUE! | B3: {=_FV(A3,"ticker symbol",TRUE)} -> DIA | C3: {=_FV(A3,"Name")} -> SPDR Dow Jones Indus Avg | D3: {=TRANSPOSE(_xlfn.STOCKHISTORY(B3, WORKDAY(TODAY(), -23), TODAY(), 0, 0, 1))} -> 461.76 | E3: 458.1 | F3: 462.57 | G3: 464.44 | H3: 471.18 | I3: 474.35 | J3: 477.18 | K3: 473.32 | L3: 475.26 | M3: 479.41 | N3: 479.07 | O3: 480.03 | P3: 478.15 | Q3: 476.42 | R3: 481.35 | S3: 487.87 | T3: 485.4 | U3: 485.17 | V3: 481.98 | W3: 479.8 | X3: 480.51 | Y3: 481.15 | AA3: =D3/D$1 -> 0.69685948 | AB3: =E3/E$1 -> 0.70203669 | AC3: =F3/F$1 -> 0.70189521 | AD3: =G3/G$1 -> 0.69451049 | AE3: =H3/H$1 -> 0.69802376 | AF3: =I3/I$1 -> 0.69790195 | AG3: =J3/J$1 -> 0.69825429 | AH3: =K3/K$1 -> 0.69578256 | ... AV3: =Y3/Y$1 -> 0.70696014
A4: #VALUE! | B4: {=_FV(A4,"ticker symbol",TRUE)} -> IWM | C4: {=_FV(A4,"Name")} -> iShares:Russ 2000 ETF | D4: {=TRANSPOSE(_xlfn.STOCKHISTORY(B4, WORKDAY(TODAY(), -23), TODAY(), 0, 0, 1))} -> 233.43 | E4: 229.11 | F4: 235.6 | G4: 239.9 | H4: 245.13 | I4: 247.3 | J4: 248.75 | K4: 245.62 | L4: 245.17 | M4: 249.63 | N4: 251.82 | O4: 250.77 | P4: 250.87 | Q4: 251.39 | R4: 254.81 | S4: 257.8 | T4: 253.85 | U4: 251.93 | V4: 249.9 | W4: 247.24 | X4: 248.71 | Y4: 250.79 | AA4: =D4/D$1 -> 0.35227804 | AB4: =E4/E$1 -> 0.35111029 | AC4: =F4/F$1 -> 0.35749511 | AD4: =G4/G$1 -> 0.3587397 | AE4: =H4/H$1 -> 0.3631448 | AF4: =I4/I$1 -> 0.36384769 | AG4: =J4/J$1 -> 0.36399421 | AH4: =K4/K$1 -> 0.36106252 | ... AV4: =Y4/Y$1 -> 0.36848911
A5: #VALUE! | B5: {=_FV(A5,"ticker symbol",TRUE)} -> RSP | C5: {=_FV(A5,"Name")} -> Invesco S&P500 EWght | D5: {=TRANSPOSE(_xlfn.STOCKHISTORY(B5, WORKDAY(TODAY(), -23), TODAY(), 0, 0, 1))} -> 184.43 | E5: 182.18 | F5: 185.76 | G5: 186.53 | H5: 189.18 | I5: 190.5 | J5: 191.53 | K5: 190.22 | L5: 190.04 | M5: 191.49 | N5: 191.55 | O5: 192 | P5: 190.85 | Q5: 190.49 | R5: 193.17 | S5: 194.73 | T5: 193.41 | U5: 193.65 | V5: 192.29 | W5: 191.77 | X5: 192.18 | Y5: 192.88 | AA5: =D5/D$1 -> 0.27833029 | AB5: =E5/E$1 -> 0.27919023 | AC5: =F5/F$1 -> 0.28186881 | AD5: =G5/G$1 -> 0.27893171 | AE5: =H5/H$1 -> 0.28025836 | AF5: =I5/I$1 -> 0.28027895 | AG5: =J5/J$1 -> 0.28026456 | AH5: =K5/K$1 -> 0.27962427 | ... AV5: =Y5/Y$1 -> 0.28340117
A6: #VALUE! | B6: {=_FV(A6,"ticker symbol",TRUE)} -> QQQE | C6: {=_FV(A6,"Name")} -> Direxion:NASDAQ-100 EWI | D6: {=TRANSPOSE(_xlfn.STOCKHISTORY(B6, WORKDAY(TODAY(), -23), TODAY(), 0, 0, 1))} -> 99.05 | E6: 96.91 | F6: 98.42 | G6: 99.58 | H6: 100.61 | I6: 101.22 | J6: 102.15 | K6: 101.78 | L6: 102.78 | M6: 103.92 | N6: 103.59 | O6: 104.08 | P6: 103.55 | Q6: 103.46 | R6: 104.44 | S6: 104.43 | T6: 103.24 | U6: 103.03 | V6: 102.8 | W6: 101.55 | X6: 102.49 | Y6: 103.27 | AA6: =D6/D$1 -> 0.1494801 | AB6: =E6/E$1 -> 0.14851424 | AC6: =F6/F$1 -> 0.1493407 | AD6: =G6/G$1 -> 0.14890913 | AE6: =H6/H$1 -> 0.14904744 | AF6: =I6/I$1 -> 0.14892302 | AG6: =J6/J$1 -> 0.14947541 | AH6: =K6/K$1 -> 0.14961706 | ... AV6: =Y6/Y$1 -> 0.15173599
A7: #VALUE! | B7: {=_FV(A7,"ticker symbol",TRUE)} -> EDOW | C7: {=_FV(A7,"Name")} -> FT:Dow 30 Equal Weight | D7: {=TRANSPOSE(_xlfn.STOCKHISTORY(B7, WORKDAY(TODAY(), -23), TODAY(), 0, 0, 1))} -> 40.0375 | E7: 39.72 | F7: 40.2046 | G7: 40.285 | H7: 40.8282 | I7: 41.0541 | J7: 41.236 | K7: 40.9993 | L7: 41.13 | M7: 41.47 | N7: 41.3567 | O7: 41.3227 | P7: 41.0972 | Q7: 40.99 | R7: 41.39 | S7: 41.7455 | T7: 41.62 | U7: 41.63 | V7: 41.36 | W7: 41.23 | X7: 41.2089 | Y7: 41.2032 | AA7: =D7/D$1 -> 0.060422106 | AB7: =E7/E$1 -> 0.060870765 | AC7: =F7/F$1 -> 0.061005721 | AD7: =G7/G$1 -> 0.060241054 | AE7: =H7/H$1 -> 0.06048443 | AF7: =I7/I$1 -> 0.060402101 | AG7: =J7/J$1 -> 0.060340362 | AH7: =K7/K$1 -> 0.060269158 | ... AV7: =Y7/Y$1 -> 0.060540413
A8: #VALUE! | B8: {=_FV(A8,"ticker symbol",TRUE)} -> MDY | C8: {=_FV(A8,"Name")} -> SPDR S&P MidCap 400 | D8: {=TRANSPOSE(_xlfn.STOCKHISTORY(B8, WORKDAY(TODAY(), -23), TODAY(), 0, 0, 1))} -> 577.89 | E8: 568.63 | F8: 582.32 | G8: 587.81 | H8: 598.88 | I8: 602.5 | J8: 605.48 | K8: 602.2 | L8: 600.02 | M8: 604.19 | N8: 607.15 | O8: 607.38 | P8: 604.34 | Q8: 603.9 | R8: 615.37 | S8: 621.24 | T8: 613.11 | U8: 611.94 | V8: 608.15 | W8: 605.4 | X8: 608.07 | Y8: 611.57 | AA8: =D8/D$1 -> 0.87211566 | AB8: =E8/E$1 -> 0.87142354 | AC8: =F8/F$1 -> 0.88360166 | AD8: =G8/G$1 -> 0.87899451 | AE8: =H8/H$1 -> 0.88720334 | AF8: =I8/I$1 -> 0.88644656 | AG8: =J8/J$1 -> 0.88599482 | AH8: =K8/K$1 -> 0.88523674 | ... AV8: =Y8/Y$1 -> 0.89858799
A9: #VALUE! | B9: {=_FV(A9,"ticker symbol",TRUE)} -> IWN | C9: {=_FV(A9,"Name")} -> iShares:Russ 2000 Vl ETF | D9: {=TRANSPOSE(_xlfn.STOCKHISTORY(B9, WORKDAY(TODAY(), -23), TODAY(), 0, 0, 1))} -> 171.2 | E9: 168.85 | F9: 173.85 | G9: 175.94 | H9: 180.15 | I9: 181.53 | J9: 182.23 | K9: 181.03 | L9: 180.29 | M9: 183.63 | N9: 183.97 | O9: 183.77 | P9: 183.52 | Q9: 184.11 | R9: 187.68 | S9: 189.45 | T9: 187.43 | U9: 186.67 | V9: 184.41 | W9: 183.65 | X9: 184.42 | Y9: 184.45 | AA9: =D9/D$1 -> 0.2583644 | AB9: =E9/E$1 -> 0.25876205 | AC9: =F9/F$1 -> 0.26379679 | AD9: =G9/G$1 -> 0.26309572 | AE9: =H9/H$1 -> 0.26688098 | AF9: =I9/I$1 -> 0.26708157 | AG9: =J9/J$1 -> 0.26665594 | AH9: =K9/K$1 -> 0.26611492 | ... AV9: =Y9/Y$1 -> 0.27101485
A10: #VALUE! | B10: {=_FV(A10,"ticker symbol",TRUE)} -> IWO | C10: {=_FV(A10,"Name")} -> iShares:Russ 2000 Gr | D10: {=TRANSPOSE(_xlfn.STOCKHISTORY(B10, WORKDAY(TODAY(), -23), TODAY(), 0, 0, 1))} -> 307.97 | E10: 300.69 | F10: 308.52 | G10: 316.08 | H10: 322.47 | I10: 325.72 | J10: 328.12 | K10: 322.28 | L10: 322.63 | M10: 328.46 | N10: 333.15 | O10: 331.15 | P10: 331.46 | Q10: 331.66 | R10: 334.44 | S10: 339.33 | T10: 332.92 | U10: 329.04 | V10: 327.47 | W10: 321.75 | X10: 324.28 | Y10: 329.61 | AA10: =D10/D$1 -> 0.46476918 | AB10: =E10/E$1 -> 0.4608064 | AC10: =F10/F$1 -> 0.46814257 | AD10: =G10/G$1 -> 0.47265713 | AE10: =H10/H$1 -> 0.47771918 | AF10: =I10/I$1 -> 0.47922552 | AG10: =J10/J$1 -> 0.48013579 | AH10: =K10/K$1 -> 0.47375307 | ... AV10: =Y10/Y$1 -> 0.48430039
A11: #VALUE! | B11: {=_FV(A11,"ticker symbol",TRUE)} -> XLC | C11: {=_FV(A11,"Name")} -> Sel Sctr:ComS SS SPDR | D11: {=TRANSPOSE(_xlfn.STOCKHISTORY(B11, WORKDAY(TODAY(), -23), TODAY(), 0, 0, 1))} -> 111.19 | E11: 109.97 | F11: 111.9 | G11: 113.01 | H11: 114.3 | I11: 114.46 | J11: 115.39 | K11: 114.85 | L11: 115.23 | M11: 115.13 | N11: 115.79 | O11: 117.13 | P11: 116.26 | Q11: 116.39 | R11: 117.07 | S11: 116.81 | T11: 116.55 | U11: 116.57 | V11: 116.65 | W11: 115.81 | X11: 116.47 | Y11: 116.52 | AA11: =D11/D$1 -> 0.16780104 | AB11: =E11/E$1 -> 0.16852865 | AC11: =F11/F$1 -> 0.169795 | AD11: =G11/G$1 -> 0.16899197 | AE11: =H11/H$1 -> 0.16932832 | AF11: =I11/I$1 -> 0.16840278 | AG11: =J11/J$1 -> 0.16884941 | AH11: =K11/K$1 -> 0.16883002 | ... AV11: =Y11/Y$1 -> 0.1712044
A12: #VALUE! | B12: {=_FV(A12,"ticker symbol",TRUE)} -> XLY | C12: {=_FV(A12,"Name")} -> Sel Sctr:C D SS SPDR In | D12: {=TRANSPOSE(_xlfn.STOCKHISTORY(B12, WORKDAY(TODAY(), -23), TODAY(), 0, 0, 1))} -> 224.51 | E12: 221.16 | F12: 225.5 | G12: 228.51 | H12: 233.4 | I12: 235 | J12: 236.46 | K12: 236.6 | L12: 118.22 | M12: 119.495 | N12: 119.07 | O12: 119.73 | P12: 117.99 | Q12: 117.98 | R12: 119.71 | S12: 120.18 | T12: 120.7 | U12: 121.73 | V12: 121.93 | W12: 120.52 | X12: 122.34 | Y12: 121.85 | AA12: =D12/D$1 -> 0.33881653 | AB12: =E12/E$1 -> 0.33892695 | AC12: =F12/F$1 -> 0.34216955 | AD12: =G12/G$1 -> 0.34170742 | AE12: =H12/H$1 -> 0.34576753 | AF12: =I12/I$1 -> 0.34575094 | AG12: =J12/J$1 -> 0.34601033 | AH12: =K12/K$1 -> 0.34780308 | ... AV12: =Y12/Y$1 -> 0.17903584
A13: #VALUE! | B13: {=_FV(A13,"ticker symbol",TRUE)} -> XLP | C13: {=_FV(A13,"Name")} -> Sel Sector:C SSS SPDR I | D13: {=TRANSPOSE(_xlfn.STOCKHISTORY(B13, WORKDAY(TODAY(), -23), TODAY(), 0, 0, 1))} -> 76.51 | E13: 77.06 | F13: 77.9 | G13: 77 | H13: 78.06 | I13: 78.91 | J13: 79.37 | K13: 79.29 | L13: 78.77 | M13: 78.83 | N13: 78.45 | O13: 78.46 | P13: 77.81 | Q13: 77.99 | R13: 78.22 | S13: 78.8 | T13: 79.42 | U13: 79.64 | V13: 79.28 | W13: 79.65 | X13: 79.19 | Y13: 78.78 | AA13: =D13/D$1 -> 0.11546414 | AB13: =E13/E$1 -> 0.11809419 | AC13: =F13/F$1 -> 0.11820403 | AD13: =G13/G$1 -> 0.11514363 | AE13: =H13/H$1 -> 0.11564102 | AF13: =I13/I$1 -> 0.11609875 | AG13: =J13/J$1 -> 0.11614159 | AH13: =K13/K$1 -> 0.11655666 | ... AV13: =Y13/Y$1 -> 0.11575251
... A107: #VALUE! | B107: {=_FV(A107,"ticker symbol",TRUE)} -> CATL | C107: {=_FV(A107,"Name")} -> WT Live Cattle | D107: {=TRANSPOSE(_xlfn.STOCKHISTORY(B107, WORKDAY(TODAY(), -23), TODAY(), 0, 0, 1))} -> 16.33 | E107: 15.13 | F107: 15.11 | G107: 15.045 | H107: 15 | I107: 15.1 | J107: 15.2 | K107: 15.57 | L107: 15.31 | M107: 15.28 | N107: 15.55 | O107: 15.6 | P107: 16.17 | Q107: 15.9 | R107: 16.13 | S107: 16.38 | T107: 16.3 | U107: 16.58 | V107: 16.32 | W107: 16.25 | X107: 15.9 | Y107: 16.3 | AA107: =D107/D$1 -> 0.024644221 | AB107: =E107/E$1 -> 0.023186673 | AC107: =F107/F$1 -> 0.022927636 | AD107: =G107/G$1 -> 0.022497869 | AE107: =H107/H$1 -> 0.022221564 | AF107: =I107/I$1 -> 0.022216337 | AG107: =J107/J$1 -> 0.022242058 | AH107: =K107/K$1 -> 0.022887971 | ... AV107: =Y107/Y$1 -> 0.023949808
A108: #VALUE! | B108: {=_FV(A108,"ticker symbol",TRUE)} -> HOGS | C108: {=_FV(A108,"Name")} -> ETFS LEAN HOGS ETC | D108: {=TRANSPOSE(_xlfn.STOCKHISTORY(B108, WORKDAY(TODAY(), -23), TODAY(), 0, 0, 1))} -> 26.31 | E108: 26.605 | F108: 26.12 | G108: 26.18 | H108: 26.27 | I108: 26.825 | J108: 26.95 | K108: 27.095 | L108: 26.79 | M108: 26.575 | N108: 26.76 | O108: 26.95 | P108: 27.245 | Q108: 27.17 | R108: 26.91 | S108: 27.27 | T108: 27.6 | U108: 27.795 | V108: 27.245 | W108: 27.68 | X108: 27.345 | Y108: 27.46 | Z108: 27.65 | AA108: =D108/D$1 -> 0.039705416 | AB108: =E108/E$1 -> 0.040772072 | AC108: =F108/F$1 -> 0.039634008 | AD108: =G108/G$1 -> 0.039148834 | AE108: =H108/H$1 -> 0.038917365 | AF108: =I108/I$1 -> 0.039467102 | AG108: =J108/J$1 -> 0.039435754 | AH108: =K108/K$1 -> 0.039829773 | ... AV108: =Y108/Y$1 -> 0.040347346
A109: #VALUE! | B109: {=_FV(A109,"ticker symbol",TRUE)} -> SLX | C109: {=_FV(A109,"Name")} -> VanEck:Steel | D109: {=TRANSPOSE(_xlfn.STOCKHISTORY(B109, WORKDAY(TODAY(), -23), TODAY(), 0, 0, 1))} -> 77.034 | E109: 75.8225 | F109: 77.36 | G109: 77.97 | H109: 79.77 | I109: 80.93 | J109: 80.86 | K109: 81.09 | L109: 81.29 | M109: 83.51 | N109: 83.32 | O109: 81.6912 | P109: 81.35 | Q109: 81.5 | R109: 83.87 | S109: 85.8 | T109: 85.16 | U109: 85.05 | V109: 84.79 | W109: 85.1 | X109: 84.86 | Y109: 84.69 | AA109: =D109/D$1 -> 0.11625492 | AB109: =E109/E$1 -> 0.11619772 | AC109: =F109/F$1 -> 0.11738464 | AD109: =G109/G$1 -> 0.11659414 | AE109: =H109/H$1 -> 0.11817428 | AF109: =I109/I$1 -> 0.11907074 | AG109: =J109/J$1 -> 0.1183219 | AH109: =K109/K$1 -> 0.11920267 | ... AV109: =Y109/Y$1 -> 0.12443615
A110: #VALUE! | B110: {=_FV(A110,"ticker symbol",TRUE)} -> SOYB | C110: {=_FV(A110,"Name")} -> Teucrium:Soybean | D110: {=TRANSPOSE(_xlfn.STOCKHISTORY(B110, WORKDAY(TODAY(), -23), TODAY(), 0, 0, 1))} -> 23.47 | E110: 23.34 | F110: 23.38 | G110: 23.32 | H110: 23.35 | I110: 23.47 | J110: 23.6 | K110: 23.47 | L110: 23.43 | M110: 23.28 | N110: 23.3 | O110: 23.03 | P110: 22.87 | Q110: 22.73 | R110: 22.78 | S110: 22.82 | T110: 22.52 | U110: 22.48 | V110: 22.29 | W110: 22.23 | X110: 22.08 | Y110: 22.01 | AA110: =D110/D$1 -> 0.035419465 | AB110: =E110/E$1 -> 0.03576847 | AC110: =F110/F$1 -> 0.035476382 | AD110: =G110/G$1 -> 0.034872071 | AE110: =H110/H$1 -> 0.034591568 | AF110: =I110/I$1 -> 0.034530956 | AG110: =J110/J$1 -> 0.034533722 | AH110: =K110/K$1 -> 0.034501007 | ... AV110: =Y110/Y$1 -> 0.032339588
A111: #VALUE! | B111: {=_FV(A111,"ticker symbol",TRUE)} -> WEAT | C111: {=_FV(A111,"Name")} -> Teucrium:Wheat | D111: {=TRANSPOSE(_xlfn.STOCKHISTORY(B111, WORKDAY(TODAY(), -23), TODAY(), 0, 0, 1))} -> 21.3 | E111: 20.95 | F111: 20.95 | G111: 20.8 | H111: 20.89 | I111: 20.96 | J111: 20.84 | K111: 20.74 | L111: 20.91 | M111: 20.85 | N111: 20.87 | O111: 20.7 | P111: 20.68 | Q111: 20.65 | R111: 20.51 | S111: 20.67 | T111: 20.53 | U111: 20.25 | V111: 19.93 | W111: 19.88 | X111: 19.94 | Y111: 19.98 | AA111: =D111/D$1 -> 0.032144636 | AB111: =E111/E$1 -> 0.032105804 | AC111: =F111/F$1 -> 0.031789145 | AD111: =G111/G$1 -> 0.031103734 | AE111: =H111/H$1 -> 0.030947231 | AF111: =I111/I$1 -> 0.030838041 | AG111: =J111/J$1 -> 0.030495032 | AH111: =K111/K$1 -> 0.030487895 | ... AV111: =Y111/Y$1 -> 0.029356882
A112: #VALUE! | B112: {=_FV(A112,"ticker symbol",TRUE)} -> DBC | C112: {=_FV(A112,"Name")} -> Invesco DB Cm Idx | D112: {=TRANSPOSE(_xlfn.STOCKHISTORY(B112, WORKDAY(TODAY(), -23), TODAY(), 0, 0, 1))} -> 22.9 | E112: 22.68 | F112: 22.53 | G112: 22.64 | H112: 22.52 | I112: 22.76 | J112: 23.06 | K112: 23.12 | L112: 23.02 | M112: 23.13 | N112: 23.19 | O112: 23.33 | P112: 23.04 | Q112: 22.99 | R112: 23.13 | S112: 23.11 | T112: 22.92 | U112: 22.81 | V112: 22.58 | W112: 22.85 | X112: 22.69 | Y112: 22.85 | AA112: =D112/D$1 -> 0.034559256 | AB112: =E112/E$1 -> 0.034757023 | AC112: =F112/F$1 -> 0.034186608 | AD112: =G112/G$1 -> 0.033855218 | AE112: =H112/H$1 -> 0.033361974 | AF112: =I112/I$1 -> 0.033486347 | AG112: =J112/J$1 -> 0.033743543 | AH112: =K112/K$1 -> 0.033986505 | ... AV112: =Y112/Y$1 -> 0.033573811
A113: #VALUE! | B113: {=_FV(A113,"ticker symbol",TRUE)} -> IEMG | C113: {=_FV(A113,"Name")} -> iShares:Core MSCI EmMkts | D113: {=TRANSPOSE(_xlfn.STOCKHISTORY(B113, WORKDAY(TODAY(), -23), TODAY(), 0, 0, 1))} -> 66.5 | E113: 65.64 | F113: 65.58 | G113: 66.25 | H113: 66.46 | I113: 66.93 | J113: 67.1 | K113: 67.04 | L113: 67.04 | M113: 67.1 | N113: 67.07 | O113: 67.43 | P113: 67.35 | Q113: 67.28 | R113: 67.93 | S113: 67.65 | T113: 66.89 | U113: 66.72 | V113: 65.15 | W113: 64.72 | X113: 65.4 | Y113: 66.09 | AA113: =D113/D$1 -> 0.10035767 | AB113: =E113/E$1 -> 0.10059308 | AC113: =F113/F$1 -> 0.099509886 | AD113: =G113/G$1 -> 0.099068383 | AE113: =H113/H$1 -> 0.098456342 | AF113: =I113/I$1 -> 0.098472811 | AG113: =J113/J$1 -> 0.09818698 | AH113: =K113/K$1 -> 0.098549106 | ... AV113: =Y113/Y$1 -> 0.097106922
A114: #VALUE! | B114: {=_FV(A114,"ticker symbol",TRUE)} -> EUE | C114: {=_FV(A114,"Name")} -> iShs Cr EUR STXX 50 ETFEURD | D114: {=TRANSPOSE(_xlfn.STOCKHISTORY(B114, WORKDAY(TODAY(), -23), TODAY(), 0, 0, 1))} -> 56.41 | E114: 56.66 | F114: 56.03 | G114: 56.27 | H114: 56.71 | I114: 57.49 | J114: 57.56 | K114: 57.7 | L114: 57.72 | M114: 57.93 | N114: 58.01 | O114: 58.25 | P114: 58.29 | Q114: 58.3 | R114: 58.25 | S114: 58.13 | T114: 58.57 | U114: 58.31 | V114: 58.53 | W114: 58.23 | X114: 57.86 | Y114: 58.46 | Z114: 58.67 | AA114: =D114/D$1 -> 0.085130465 | AB114: =E114/E$1 -> 0.086831257 | AC114: =F114/F$1 -> 0.085018891 | AD114: =G114/G$1 -> 0.084144573 | AE114: =H114/H$1 -> 0.084012326 | AF114: =I114/I$1 -> 0.084583922 | AG114: =J114/J$1 -> 0.084227162 | AH114: =K114/K$1 -> 0.084819263 | ... AV114: =Y114/Y$1 -> 0.085896061
A115: #VALUE! | B115: {=_FV(A115,"ticker symbol",TRUE)} -> C6E | C115: {=_FV(A115,"Name")} -> Amundi StoxxEupe600 ESG UETF A | D115: {=TRANSPOSE(_xlfn.STOCKHISTORY(B115, WORKDAY(TODAY(), -23), TODAY(), 0, 0, 1))} -> 140.0011 | E115: 140.3543 | F115: 140.3535 | G115: 140.7511 | H115: 142.0768 | I115: 143.6791 | J115: 143.801 | K115: 144.1775 | L115: #N/A | M115: 144.32 | N115: #N/A | O115: 144.74 | P115: 145.32 | Q115: 144.28 | R115: 144.34 | S115: 144.14 | T115: 145.1 | U115: 144.76 | V115: 145.7 | W115: 145.96 | X115: 145.74 | Y115: #N/A | Z115: 147.08 | AA115: =D115/D$1 -> 0.21128096 | AB115: =E115/E$1 -> 0.21509249 | AC115: =F115/F$1 -> 0.21296982 | AD115: =G115/G$1 -> 0.21047523 | AE115: =H115/H$1 -> 0.21047791 | AF115: =I115/I$1 -> 0.21139227 | AG115: =J115/J$1 -> 0.21042304 | AH115: =K115/K$1 -> 0.21194158 | ... AV115: =Y115/Y$1 -> #N/A
A116: #VALUE! | B116: {=_FV(A116,"ticker symbol",TRUE)} -> FEZ | C116: {=_FV(A116,"Name")} -> SPDR EURO STOXX 50 | D116: {=TRANSPOSE(_xlfn.STOCKHISTORY(B116, WORKDAY(TODAY(), -23), TODAY(), 0, 0, 1))} -> 61.33 | E116: 60.46 | F116: 61.06 | G116: 60.98 | H116: 61.97 | I116: 62.73 | J116: 63.08 | K116: 62.98 | L116: 63.48 | M116: 63.88 | N116: 63.83 | O116: 63.84 | P116: 63.8 | Q116: 63.62 | R116: 64.28 | S116: 64.95 | T116: 64.44 | U116: 64.73 | V116: 64.54 | W116: 63.8 | X116: 64.29 | Y116: 64.62 | AA116: =D116/D$1 -> 0.092555423 | AB116: =E116/E$1 -> 0.092654744 | AC116: =F116/F$1 -> 0.092651321 | AD116: =G116/G$1 -> 0.091187774 | AE116: =H116/H$1 -> 0.091804687 | AF116: =I116/I$1 -> 0.092293432 | AG116: =J116/J$1 -> 0.092304541 | AH116: =K116/K$1 -> 0.092580887 | ... AV116: =Y116/Y$1 -> 0.094947031
A117: #VALUE! | B117: {=_FV(A117,"ticker symbol",TRUE)} -> E40 | C117: {=_FV(A117,"Name")} -> BNPP Easy CAC 40 ESG UCITS ETF | D117: {=TRANSPOSE(_xlfn.STOCKHISTORY(B117, WORKDAY(TODAY(), -23), TODAY(), 0, 0, 1))} -> 12.85 | E117: 12.894 | F117: 12.908 | G117: 12.84 | H117: 12.986 | I117: 13.054 | J117: 13.064 | K117: 13.142 | L117: 13.068 | M117: 13.02 | N117: 13.076 | O117: 13.142 | P117: 13.122 | Q117: 13.098 | R117: 13.02 | S117: 12.982 | T117: 13.068 | U117: 13.068 | V117: 13.154 | W117: 13.144 | X117: 13.076 | Y117: 13.18 | Z117: 13.174 | AA117: =D117/D$1 -> 0.019392421 | AB117: =E117/E$1 -> 0.019760011 | AC117: =F117/F$1 -> 0.019586362 | AD117: =G117/G$1 -> 0.019200574 | AE117: =H117/H$1 -> 0.019237949 | AF117: =I117/I$1 -> 0.019206097 | AG117: =J117/J$1 -> 0.019116464 | AH117: =K117/K$1 -> 0.0193188 | ... AV117: =Y117/Y$1 -> 0.01936555
A118: #VALUE! | B118: {=_FV(A118,"ticker symbol",TRUE)} -> DAX | C118: {=_FV(A118,"Name")} -> Glbl X DAX Germany | D118: {=TRANSPOSE(_xlfn.STOCKHISTORY(B118, WORKDAY(TODAY(), -23), TODAY(), 0, 0, 1))} -> 42.6153 | E118: 42.035 | F118: 42.5524 | G118: 42.5951 | H118: 43.31 | I118: 43.745 | J118: 44.0141 | K118: 43.515 | L118: 43.87 | M118: 44.11 | N118: 44.219 | O118: 44.4904 | P118: 44.4 | Q118: 44.59 | R118: 45.005 | S118: 45.56 | T118: 45.25 | U118: 45.22 | V118: 45.085 | W118: 44.6511 | X118: 44.96 | Y118: 45.16 | AA118: =D118/D$1 -> 0.064312361 | AB118: =E118/E$1 -> 0.064418494 | AC118: =F118/F$1 -> 0.064568229 | AD118: =G118/G$1 -> 0.063695512 | AE118: =H118/H$1 -> 0.064161062 | AF118: =I118/I$1 -> 0.06436117 | AG118: =J118/J$1 -> 0.064405537 | AH118: =K118/K$1 -> 0.063967248 | ... AV118: =Y118/Y$1 -> 0.066354193
A119: #VALUE! | B119: {=_FV(A119,"ticker symbol",TRUE)} -> ISF | C119: {=_FV(A119,"Name")} -> iShs Cr FTSE 100 ETF GBPD | D119: {=TRANSPOSE(_xlfn.STOCKHISTORY(B119, WORKDAY(TODAY(), -23), TODAY(), 0, 0, 1))} -> 10.528 | E119: 10.566 | F119: 10.594 | G119: 10.61 | H119: 10.7 | I119: 10.81 | J119: 10.824 | K119: 10.852 | L119: 10.804 | M119: 10.786 | N119: 10.85 | O119: 10.9 | P119: 10.848 | Q119: 10.162 | R119: 10.134 | S119: 10.108 | T119: 10.074 | U119: 9.982 | V119: 10.118 | W119: 10.034 | X119: 10.15 | Y119: 10.166 | Z119: 10.254 | AA119: =D119/D$1 -> 0.015888203 | AB119: =E119/E$1 -> 0.016192359 | AC119: =F119/F$1 -> 0.016075141 | AD119: =G119/G$1 -> 0.015865895 | AE119: =H119/H$1 -> 0.015851382 | AF119: =I119/I$1 -> 0.015904543 | AG119: =J119/J$1 -> 0.015838687 | AH119: =K119/K$1 -> 0.015952489 | ... AV119: =Y119/Y$1 -> 0.01493704
A120: #VALUE! | B120: {=_FV(A120,"ticker symbol",TRUE)} -> FXI | C120: {=_FV(A120,"Name")} -> iShares:China Large Cp | D120: {=TRANSPOSE(_xlfn.STOCKHISTORY(B120, WORKDAY(TODAY(), -23), TODAY(), 0, 0, 1))} -> 39.11 | E120: 38.58 | F120: 38.72 | G120: 39.35 | H120: 39.6 | I120: 39.37 | J120: 39.53 | K120: 39.64 | L120: 39.49 | M120: 39.21 | N120: 39.31 | O120: 39.89 | P120: 39.47 | Q120: 38.82 | R120: 39.09 | S120: 39.19 | T120: 39.08 | U120: 38.74 | V120: 37.96 | W120: 37.85 | X120: 38.21 | Y120: 38.6 | AA120: =D120/D$1 -> 0.059022381 | AB120: =E120/E$1 -> 0.059123718 | AC120: =F120/F$1 -> 0.058753016 | AD120: =G120/G$1 -> 0.058842881 | AE120: =H120/H$1 -> 0.058664928 | AF120: =I120/I$1 -> 0.057924317 | AG120: =J120/J$1 -> 0.057843984 | AH120: =K120/K$1 -> 0.058270981 | ... AV120: =Y120/Y$1 -> 0.056715497
A121: #VALUE! | B121: {=_FV(A121,"ticker symbol",TRUE)} -> EEM | C121: {=_FV(A121,"Name")} -> iShares:MSCI Em Mkts | D121: {=TRANSPOSE(_xlfn.STOCKHISTORY(B121, WORKDAY(TODAY(), -23), TODAY(), 0, 0, 1))} -> 53.85 | E121: 53.11 | F121: 53.1 | G121: 53.66 | H121: 53.85 | I121: 54.24 | J121: 54.32 | K121: 54.28 | L121: 54.3 | M121: 54.34 | N121: 54.33 | O121: 54.74 | P121: 54.62 | Q121: 54.53 | R121: 55.14 | S121: 54.88 | T121: 54.24 | U121: 54.08 | V121: 52.98 | W121: 52.6 | X121: 53.2 | Y121: 53.72 | AA121: =D121/D$1 -> 0.081267072 | AB121: =E121/E$1 -> 0.081390894 | AC121: =F121/F$1 -> 0.080572963 | AD121: =G121/G$1 -> 0.080241652 | AE121: =H121/H$1 -> 0.079775414 | AF121: =I121/I$1 -> 0.07980226 | AG121: =J121/J$1 -> 0.079486091 | AH121: =K121/K$1 -> 0.079791847 | ... AV121: =Y121/Y$1 -> 0.078931515
A122: #VALUE! | B122: {=_FV(A122,"ticker symbol",TRUE)} -> EWJ | C122: {=_FV(A122,"Name")} -> iShares:MSCI Japan | D122: {=TRANSPOSE(_xlfn.STOCKHISTORY(B122, WORKDAY(TODAY(), -23), TODAY(), 0, 0, 1))} -> 80.68 | E122: 79.49 | F122: 81.19 | G122: 81.74 | H122: 81.92 | I122: 83.26 | J122: 83.01 | K122: 82.53 | L122: 82.47 | M122: 82.61 | N122: 83.62 | O122: 83.7 | P122: 83.19 | Q122: 83.31 | R122: 83.91 | S122: 84.22 | T122: 84 | U122: 84.87 | V122: 80.85 | W122: 79.74 | X122: 79.97 | Y122: 80.58 | AA122: =D122/D$1 -> 0.12175724 | AB122: =E122/E$1 -> 0.12181815 | AC122: =F122/F$1 -> 0.12319621 | AD122: =G122/G$1 -> 0.12223169 | AE122: =H122/H$1 -> 0.12135937 | AF122: =I122/I$1 -> 0.12249882 | AG122: =J122/J$1 -> 0.12146798 | AH122: =K122/K$1 -> 0.12131948 | ... AV122: =Y122/Y$1 -> 0.11839727
A123: #VALUE! | B123: {=_FV(A123,"ticker symbol",TRUE)} -> EWU | C123: {=_FV(A123,"Name")} -> iShares:MSCI UK | D123: {=TRANSPOSE(_xlfn.STOCKHISTORY(B123, WORKDAY(TODAY(), -23), TODAY(), 0, 0, 1))} -> 41.73 | E123: 41.34 | F123: 42.06 | G123: 41.92 | H123: 42.52 | I123: 42.99 | J123: 43.15 | K123: 42.93 | L123: 43.01 | M123: 43.46 | N123: 43.42 | O123: 43.22 | P123: 43.08 | Q123: 42.88 | R123: 43.46 | S123: 43.65 | T123: 43.28 | U123: 43.75 | V123: 42.73 | W123: 42.94 | X123: 43.13 | Y123: 43.54 | AA123: =D123/D$1 -> 0.062976322 | AB123: =E123/E$1 -> 0.063353409 | AC123: =F123/F$1 -> 0.06382107 | AD123: =G123/G$1 -> 0.062685987 | AE123: =H123/H$1 -> 0.062990726 | AF123: =I123/I$1 -> 0.063250353 | AG123: =J123/J$1 -> 0.063141105 | AH123: =K123/K$1 -> 0.063107296 | ... AV123: =Y123/Y$1 -> 0.063973905
A124: #VALUE! | B124: {=_FV(A124,"ticker symbol",TRUE)} -> EWZ | C124: {=_FV(A124,"Name")} -> iShares:MSCI Brazil | D124: {=TRANSPOSE(_xlfn.STOCKHISTORY(B124, WORKDAY(TODAY(), -23), TODAY(), 0, 0, 1))} -> 32.49 | E124: 31.9 | F124: 32.03 | G124: 32.2 | H124: 32.55 | I124: 33.47 | J124: 33.61 | K124: 33.4 | L124: 34.03 | M124: 34.2 | N124: 34.72 | O124: 32.53 | P124: 32.75 | Q124: 32.74 | R124: 32.77 | S124: 33.16 | T124: 33.32 | U124: 33.58 | V124: 31.6 | W124: 31 | X124: 31.17 | Y124: 31.17 | AA124: =D124/D$1 -> 0.049031888 | AB124: =E124/E$1 -> 0.048886641 | AC124: =F124/F$1 -> 0.048601733 | AD124: =G124/G$1 -> 0.048150973 | AE124: =H124/H$1 -> 0.048220793 | AF124: =I124/I$1 -> 0.049243762 | AG124: =J124/J$1 -> 0.049181287 | AH124: =K124/K$1 -> 0.049098152 | ... AV124: =Y124/Y$1 -> 0.045798498
A125: #VALUE! | B125: {=_FV(A125,"ticker symbol",TRUE)} -> EWG | C125: {=_FV(A125,"Name")} -> iShares:MSCI Germany | D125: {=TRANSPOSE(_xlfn.STOCKHISTORY(B125, WORKDAY(TODAY(), -23), TODAY(), 0, 0, 1))} -> #N/A | E125: #N/A | F125: #N/A | G125: #N/A | H125: #N/A | I125: #N/A | J125: #N/A | K125: #N/A | L125: 40.52 | M125: 40.89 | N125: 40.95 | O125: 41.14 | P125: 41.41 | Q125: 41.34 | R125: 41.53 | S125: 41.94 | T125: 42.39 | U125: 42.18 | V125: 42.1 | W125: 42.03 | X125: 41.61 | Y125: 41.94 | Z125: 42.1 | AA125: =D125/D$1 -> #N/A | AB125: =E125/E$1 -> #N/A | AC125: =F125/F$1 -> #N/A | AD125: =G125/G$1 -> #N/A | AE125: =H125/H$1 -> #N/A | AF125: =I125/I$1 -> #N/A | AG125: =J125/J$1 -> #N/A | AH125: =K125/K$1 -> #N/A | ... AV125: =Y125/Y$1 -> 0.061623004
A126: #VALUE! | B126: {=_FV(A126,"ticker symbol",TRUE)} -> EWT | C126: {=_FV(A126,"Name")} -> iShares:MSCI Taiwan | D126: {=TRANSPOSE(_xlfn.STOCKHISTORY(B126, WORKDAY(TODAY(), -23), TODAY(), 0, 0, 1))} -> 62.5 | E126: 61.68 | F126: 61.8 | G126: 62.51 | H126: 62.8 | I126: 63.66 | J126: 64.51 | K126: 64.13 | L126: 64.63 | M126: 64.85 | N126: 64.51 | O126: 65.35 | P126: 65.57 | Q126: 65.72 | R126: 66.8 | S126: 65.92 | T126: 64.1 | U126: 64.11 | V126: 61.12 | W126: 60.03 | X126: 60.87 | Y126: 61.64 | AA126: =D126/D$1 -> 0.094321114 | AB126: =E126/E$1 -> 0.09452439 | AC126: =F126/F$1 -> 0.093774183 | AD126: =G126/G$1 -> 0.093475693 | AE126: =H126/H$1 -> 0.09303428 | AF126: =I126/I$1 -> 0.093661723 | AG126: =J126/J$1 -> 0.09439705 | AH126: =K126/K$1 -> 0.094271392 | ... AV126: =Y126/Y$1 -> 0.090568477
A127: #VALUE! | B127: {=_FV(A127,"ticker symbol",TRUE)} -> EWH | C127: {=_FV(A127,"Name")} -> iShares:MSCI Hong Kong | D127: {=TRANSPOSE(_xlfn.STOCKHISTORY(B127, WORKDAY(TODAY(), -23), TODAY(), 0, 0, 1))} -> 21.89 | E127: 21.64 | F127: 21.7 | G127: 22.13 | H127: 22.15 | I127: 22.16 | J127: 22.24 | K127: 22.26 | L127: 22.18 | M127: 22.23 | N127: 22.08 | O127: 22.05 | P127: 21.82 | Q127: 21.69 | R127: 21.82 | S127: 21.91 | T127: 21.87 | U127: 22.02 | V127: 21.14 | W127: 21.07 | X127: 21.44 | Y127: 21.61 | AA127: =D127/D$1 -> 0.033035027 | AB127: =E127/E$1 -> 0.033163226 | AC127: =F127/F$1 -> 0.032927181 | AD127: =G127/G$1 -> 0.033092578 | AE127: =H127/H$1 -> 0.032813843 | AF127: =I127/I$1 -> 0.032603578 | AG127: =J127/J$1 -> 0.032543643 | AH127: =K127/K$1 -> 0.032722301 | ... AV127: =Y127/Y$1 -> 0.031751862
A128: #VALUE! | B128: {=_FV(A128,"ticker symbol",TRUE)} -> EWI | C128: {=_FV(A128,"Name")} -> iShares:MSCI Italy | D128: {=TRANSPOSE(_xlfn.STOCKHISTORY(B128, WORKDAY(TODAY(), -23), TODAY(), 0, 0, 1))} -> 51.34 | E128: 50.81 | F128: 51.47 | G128: 51.19 | H128: 52.16 | I128: 52.54 | J128: 52.93 | K128: 52.66 | L128: 53 | M128: 53.29 | N128: 53.15 | O128: 52.98 | P128: 52.98 | Q128: 53.02 | R128: 53.55 | S128: 53.95 | T128: 53.66 | U128: 54.35 | V128: 53.58 | W128: 53.51 | X128: 53.81 | Y128: 54.21 | AA128: =D128/D$1 -> 0.077479136 | AB128: =E128/E$1 -> 0.077866152 | AC128: =F128/F$1 -> 0.078099631 | AD128: =G128/G$1 -> 0.076548084 | AE128: =H128/H$1 -> 0.077271785 | AF128: =I128/I$1 -> 0.077301083 | AG128: =J128/J$1 -> 0.077452114 | AH128: =K128/K$1 -> 0.07741044 | ... AV128: =Y128/Y$1 -> 0.079651479
A129: #VALUE! | B129: {=_FV(A129,"ticker symbol",TRUE)} -> EWW | C129: {=_FV(A129,"Name")} -> iShares:MSCI Mexico | D129: {=TRANSPOSE(_xlfn.STOCKHISTORY(B129, WORKDAY(TODAY(), -23), TODAY(), 0, 0, 1))} -> 66.77 | E129: 66.02 | F129: 66.04 | G129: 66.55 | H129: 67.75 | I129: 67.88 | J129: 68.42 | K129: 68.46 | L129: 68.71 | M129: 68.43 | N129: 68.82 | O129: 68.68 | P129: 68.64 | Q129: 69.27 | R129: 69.04 | S129: 71.06 | T129: 70.69 | U129: 70.48 | V129: 68.28 | W129: 67.45 | X129: 68.75 | Y129: 68.85 | AA129: =D129/D$1 -> 0.10076513 | AB129: =E129/E$1 -> 0.10117542 | AC129: =F129/F$1 -> 0.10020788 | AD129: =G129/G$1 -> 0.099516995 | AE129: =H129/H$1 -> 0.1003674 | AF129: =I129/I$1 -> 0.099870527 | AG129: =J129/J$1 -> 0.10011853 | AH129: =K129/K$1 -> 0.10063651 | ... AV129: =Y129/Y$1 -> 0.10116223
A130: #VALUE! | B130: {=_FV(A130,"ticker symbol",TRUE)} -> PIN | C130: {=_FV(A130,"Name")} -> Invesco India | D130: {=TRANSPOSE(_xlfn.STOCKHISTORY(B130, WORKDAY(TODAY(), -23), TODAY(), 0, 0, 1))} -> 26.48 | E130: 26.42 | F130: 26.1393 | G130: 26.1311 | H130: 26.1 | I130: 26.28 | J130: 26.45 | K130: 26.2 | L130: 25.975 | M130: 25.71 | N130: 25.96 | O130: 26.03 | P130: 25.5905 | Q130: 25.67 | R130: 25.7415 | S130: 25.75 | T130: 25.57 | U130: 25.6 | V130: 25.5 | W130: 25.51 | X130: 25.69 | Y130: 26.14 | AA130: =D130/D$1 -> 0.03996197 | AB130: =E130/E$1 -> 0.04048856 | AC130: =F130/F$1 -> 0.039663293 | AD130: =G130/G$1 -> 0.039075711 | AE130: =H130/H$1 -> 0.038665521 | AF130: =I130/I$1 -> 0.038665254 | AG130: =J130/J$1 -> 0.038704107 | AH130: =K130/K$1 -> 0.038514119 | ... AV130: =Y130/Y$1 -> 0.038407852
A131: #VALUE! | B131: {=_FV(A131,"ticker symbol",TRUE)} -> IDX | C131: {=_FV(A131,"Name")} -> VanEck:Indonesia Index | D131: {=TRANSPOSE(_xlfn.STOCKHISTORY(B131, WORKDAY(TODAY(), -23), TODAY(), 0, 0, 1))} -> 16.68 | E131: 16.53 | F131: 16.69 | G131: 17.08 | H131: 17.0102 | I131: 17.13 | J131: 17.01 | K131: 17.1 | L131: 17.24 | M131: 17.14 | N131: 17.12 | O131: 17.1 | P131: 17.25 | Q131: 17.11 | R131: 17.29 | S131: 17.15 | T131: 17.18 | U131: 17.14 | V131: 17.3 | W131: 17.17 | X131: 17.2 | Y131: 17.21 | AA131: =D131/D$1 -> 0.025172419 | AB131: =E131/E$1 -> 0.025332169 | AC131: =F131/F$1 -> 0.025325099 | AD131: =G131/G$1 -> 0.025540951 | AE131: =H131/H$1 -> 0.02519955 | AF131: =I131/I$1 -> 0.025203037 | AG131: =J131/J$1 -> 0.024890619 | AH131: =K131/K$1 -> 0.025137078 | ... AV131: =Y131/Y$1 -> 0.025286883
A132: #VALUE! | B132: {=_FV(A132,"ticker symbol",TRUE)} -> EWY | C132: {=_FV(A132,"Name")} -> iShares:MSCI S Korea | D132: {=TRANSPOSE(_xlfn.STOCKHISTORY(B132, WORKDAY(TODAY(), -23), TODAY(), 0, 0, 1))} -> 90.56 | E132: 88.53 | F132: 89.22 | G132: 90.3 | H132: 89.79 | I132: 91.55 | J132: 90.87 | K132: 90.62 | L132: 92.07 | M132: 93 | N132: 91.87 | O132: 94.3 | P132: 95.07 | Q132: 95.57 | R132: 96.75 | S132: 94.96 | T132: 92.67 | U132: 92.73 | V132: 89.52 | W132: 88.58 | X132: 90.07 | Y132: 91.34 | AA132: =D132/D$1 -> 0.13666752 | AB132: =E132/E$1 -> 0.13567192 | AC132: =F132/F$1 -> 0.13538079 | AD132: =G132/G$1 -> 0.13503208 | AE132: =H132/H$1 -> 0.13301828 | AF132: =I132/I$1 -> 0.13469574 | AG132: =J132/J$1 -> 0.13296946 | AH132: =K132/K$1 -> 0.13321181 | ... AV132: =Y132/Y$1 -> 0.13420709
A133: #VALUE! | B133: {=_FV(A133,"ticker symbol",TRUE)} -> EWA | C133: {=_FV(A133,"Name")} -> iShares:MSCI Australia | D133: {=TRANSPOSE(_xlfn.STOCKHISTORY(B133, WORKDAY(TODAY(), -23), TODAY(), 0, 0, 1))} -> 25.3 | E133: 24.95 | F133: 25.33 | G133: 25.44 | H133: 25.62 | I133: 25.82 | J133: 25.85 | K133: 25.73 | L133: 25.93 | M133: 26.13 | N133: 26.29 | O133: 26.34 | P133: 26.24 | Q133: 26.35 | R133: 26.65 | S133: 26.64 | T133: 26.52 | U133: 26.42 | V133: 25.82 | W133: 25.58 | X133: 25.81 | Y133: 25.88 | AA133: =D133/D$1 -> 0.038181187 | AB133: =E133/E$1 -> 0.03823579 | AC133: =F133/F$1 -> 0.038435276 | AD133: =G133/G$1 -> 0.038042259 | AE133: =H133/H$1 -> 0.037954431 | AF133: =I133/I$1 -> 0.037988465 | AG133: =J133/J$1 -> 0.037826131 | AH133: =K133/K$1 -> 0.037823217 | ... AV133: =Y133/Y$1 -> 0.038025831
...

Sheet Price
A1: #VALUE! | B1: {=_FV(A1,"ticker symbol",TRUE)} -> SPY | C1: {=_FV(A1,"Name")} -> SPDR S&P 500 | D1: {=TRANSPOSE(_xlfn.STOCKHISTORY(B1, WORKDAY(TODAY(), -265), TODAY(), 0, 0, 1))} -> 606.79 | E1: 604.29 | F1: 586.28 | G1: 586.1 | H1: 591.15 | I1: 594.69 | J1: 601.3 | K1: 601.34 | L1: 595.01 | M1: 588.22 | N1: 586.08 | O1: 584.64 | P1: 591.95 | Q1: 595.36 | R1: 588.63 | S1: 589.49 | T1: 580.49 | U1: 581.39 | V1: 582.19 | W1: 592.78 | X1: 591.64 | Y1: 597.58 | Z1: 603.05 | AA1: 606.44 | AB1: 609.75 | AC1: 607.97 | AD1: 599.37 | AE1: 604.52 | AF1: 601.81 | AG1: 605.04 | AH1: 601.82 | AI1: 597.77 | AJ1: 601.78 | AK1: 604.22 | AL1: 606.32 | AM1: 600.77 | AN1: 604.85 | AO1: 605.31 | AP1: 603.36 | AQ1: 609.73 | AR1: 609.7 | AS1: 611.49 | AT1: 612.93 | AU1: 610.38 | AV1: 599.94 | AW1: 597.21 | AX1: 594.24 | AY1: 594.54 | AZ1: 585.05 | BA1: 594.18 | BB1: 583.77 | BC1: 576.86 | BD1: 583.06 | BE1: 572.71 | BF1: 575.92 | BG1: 560.58 | BH1: 555.92 | BI1: 558.87 | BJ1: 551.42 | BK1: 562.81 | BL1: 567.15 | BM1: 561.02 | BN1: 567.13 | BO1: 565.49 | BP1: 563.98 | BQ1: 574.08 | BR1: 575.46 | BS1: 568.59 | BT1: 567.08 | BU1: 555.66 | BV1: 559.39 | BW1: 560.97 | BX1: 564.52 | BY1: 536.7 | BZ1: 505.28 | CA1: 504.38 | CB1: 496.48 | CC1: 548.62 | CD1: 524.58 | CE1: 533.94 | CF1: 539.12 | CG1: 537.61 | CH1: 525.66 | CI1: 526.41 | CJ1: 513.88 | CK1: 527.25 | CL1: 535.42 | CM1: 546.69 | CN1: 550.64 | CO1: 550.85 | CP1: 554.32 | CQ1: 554.54 | CR1: 558.47 | CS1: 566.76 | CT1: 563.51 | CU1: 558.8 | CV1: 561.15 | CW1: 565.06 | CX1: 564.34 | CY1: 582.99 | CZ1: 586.84 | DA1: 587.59 | DB1: 590.46 | DC1: 594.2 | DD1: 594.85 | DE1: 592.85 | DF1: 582.86 | DG1: 583.09 | DH1: 579.11 | DI1: 591.15 | DJ1: 587.73 | DK1: 590.05 | DL1: 589.39 | DM1: 592.71 | DN1: 596.09 | DO1: 595.93 | DP1: 593.05 | DQ1: 599.14 | DR1: 599.68 | DS1: 603.08 | DT1: 601.36 | DU1: 603.75 | DV1: 597 | DW1: 602.68 | DX1: 597.53 | DY1: 597.44 | DZ1: 594.28 | EA1: 600.15 | EB1: 606.78 | EC1: 607.12 | ED1: 611.87 | EE1: 614.91 | EF1: 617.85 | EG1: 617.65 | EH1: 620.45 | EI1: 625.34 | EJ1: 620.68 | EK1: 620.34 | EL1: 624.06 | EM1: 625.82 | EN1: 623.62 | EO1: 624.81 | EP1: 622.14 | EQ1: 624.22 | ER1: 628.04 | ES1: 627.58 | ET1: 628.77 | EU1: 628.86 | EV1: 634.21 | EW1: 634.42 | EX1: 637.1 | EY1: 636.94 | EZ1: 635.26 | FA1: 634.46 | FB1: 632.08 | FC1: 621.72 | FD1: 631.17 | FE1: 627.97 | FF1: 632.78 | FG1: 632.25 | FH1: 637.18 | FI1: 635.92 | FJ1: 642.69 | FK1: 644.89 | FL1: 644.95 | FM1: 643.44 | FN1: 643.3 | FO1: 639.81 | FP1: 638.11 | FQ1: 635.55 | FR1: 645.31 | FS1: 642.47 | FT1: 645.16 | FU1: 646.63 | FV1: 648.92 | FW1: 645.05 | FX1: 640.27 | FY1: 643.74 | FZ1: 649.12 | GA1: 647.24 | GB1: 648.83 | GC1: 650.33 | GD1: 652.21 | GE1: 657.63 | GF1: 657.41 | GG1: 660.91 | GH1: 660 | GI1: 659.18 | GJ1: 662.26 | GK1: 663.7 | GL1: 666.84 | GM1: 663.21 | GN1: 661.1 | GO1: 658.05 | GP1: 661.82 | GQ1: 663.68 | GR1: 666.18 | GS1: 668.45 | GT1: 669.22 | GU1: 669.21 | GV1: 671.61 | GW1: 669.12 | GX1: 673.11 | GY1: 671.16 | GZ1: 653.02 | HA1: 663.04 | HB1: 662.23 | HC1: 665.17 | HD1: 660.64 | HE1: 664.39 | HF1: 671.3 | HG1: 671.29 | HH1: 667.8 | HI1: 671.76 | HJ1: 677.25 | HK1: 685.24 | HL1: 687.06 | HM1: 687.39 | HN1: 679.83 | HO1: 682.06 | HP1: 683.34 | HQ1: 675.24 | HR1: 677.58 | HS1: 670.31 | HT1: 670.97 | HU1: 681.44 | HV1: 683 | HW1: 683.38 | HX1: 672.04 | HY1: 671.93 | HZ1: 665.67 | IA1: 660.08 | IB1: 662.63 | IC1: 652.53 | ID1: 659.03 | IE1: 668.73 | IF1: 675.02 | IG1: 679.68 | IH1: 683.39 | II1: 680.27 | IJ1: 681.53 | IK1: 683.89 | IL1: 684.39 | IM1: 685.69 | IN1: 683.63 | IO1: 683.04 | IP1: 687.57 | IQ1: 689.17 | IR1: 681.76 | IS1: 680.73 | IT1: 678.87 | IU1: 671.4 | IV1: 676.47 | IW1: 680.59
